Logged run to: results_and_data/results/e1_temperature_comparison/llama_3_forward_training_test/train/forwardsft_runs.txt
Loading model: meta-llama/Llama-3.1-8B-Instruct
Loading checkpoint shards: 100%|███████████████████████████████████████████████████████████████| 4/4 [00:05<00:00,  1.50s/it]
Loading SFT training data...
Loading results_and_data/results/e1_temperature_comparison/llama_3_forward_training_test/train/model_summaries/T0.0_trial0_stylesun.csv
Found 1 trial files
Combined data: 580 training examples from 1 trials
Loaded 580 training examples
Creating training pairs...
Creating training pairs:   0%|                                                      | 0/580 [00:00<?, ?it/s]
Traceback (most recent call last):
  File "/scratch/anaconda3/envs/myenv/lib/python3.11/site-packages/pandas/core/indexes/base.py", line 3812, in get_loc
    return self._engine.get_loc(casted_key)
           ^^^^^^^^^^^^^^^^^^^^^^^^^^^^^^^^
  File "pandas/_libs/index.pyx", line 167, in pandas._libs.index.IndexEngine.get_loc
  File "pandas/_libs/index.pyx", line 196, in pandas._libs.index.IndexEngine.get_loc
  File "pandas/_libs/hashtable_class_helper.pxi", line 7088, in pandas._libs.hashtable.PyObjectHashTable.get_item
  File "pandas/_libs/hashtable_class_helper.pxi", line 7096, in pandas._libs.hashtable.PyObjectHashTable.get_item
KeyError: 'summary'

The above exception was the direct cause of the following exception:

Traceback (most recent call last):
  File "<frozen runpy>", line 198, in _run_module_as_main
  File "<frozen runpy>", line 88, in _run_code
  File "/homes/pr450/repos/mr_repos/forced_recog/forward_sft.py", line 390, in <module>
    main()
  File "/homes/pr450/repos/mr_repos/forced_recog/forward_sft.py", line 282, in main
    training_pairs = create_training_pairs(sft_data, args.dataset, chat_wrapper)
                     ^^^^^^^^^^^^^^^^^^^^^^^^^^^^^^^^^^^^^^^^^^^^^^^^^^^^^^^^^^^
  File "/homes/pr450/repos/mr_repos/forced_recog/forward_sft.py", line 97, in create_training_pairs
    target = row['summary']
             ~~~^^^^^^^^^^^
  File "/scratch/anaconda3/envs/myenv/lib/python3.11/site-packages/pandas/core/series.py", line 1130, in __getitem__
    return self._get_value(key)
           ^^^^^^^^^^^^^^^^^^^^
  File "/scratch/anaconda3/envs/myenv/lib/python3.11/site-packages/pandas/core/series.py", line 1246, in _get_value
    loc = self.index.get_loc(label)
          ^^^^^^^^^^^^^^^^^^^^^^^^^
  File "/scratch/anaconda3/envs/myenv/lib/python3.11/site-packages/pandas/core/indexes/base.py", line 3819, in get_loc
    raise KeyError(key) from err
KeyError: 'summary'
