2025-09-01 13:31:03,442 INFO    MainThread:2472110 [wandb_setup.py:_flush():81] Current SDK version is 0.21.3
2025-09-01 13:31:03,442 INFO    MainThread:2472110 [wandb_setup.py:_flush():81] Configure stats pid to 2472110
2025-09-01 13:31:03,442 INFO    MainThread:2472110 [wandb_setup.py:_flush():81] Loading settings from /homes/pr450/.config/wandb/settings
2025-09-01 13:31:03,443 INFO    MainThread:2472110 [wandb_setup.py:_flush():81] Loading settings from /homes/pr450/repos/mr_repos/forced_recog/wandb/settings
2025-09-01 13:31:03,443 INFO    MainThread:2472110 [wandb_setup.py:_flush():81] Loading settings from environment variables
2025-09-01 13:31:03,443 INFO    MainThread:2472110 [wandb_init.py:setup_run_log_directory():686] Logging user logs to /homes/pr450/repos/mr_repos/forced_recog/wandb/run-20250901_133103-zegyoqym/logs/debug.log
2025-09-01 13:31:03,444 INFO    MainThread:2472110 [wandb_init.py:setup_run_log_directory():687] Logging internal logs to /homes/pr450/repos/mr_repos/forced_recog/wandb/run-20250901_133103-zegyoqym/logs/debug-internal.log
2025-09-01 13:31:03,444 INFO    MainThread:2472110 [wandb_init.py:init():813] calling init triggers
2025-09-01 13:31:03,445 INFO    MainThread:2472110 [wandb_init.py:init():818] wandb.init called with sweep_config: {}
config: {'run_name': 'llama_3_forward_training_test', 'dataset': 'cnn_dailymail', 'model_name': 'meta-llama/Llama-3.1-8B-Instruct', 'temperature': 0.0, 'style': 'sun', 'sft_config': {'lora_r': 16, 'lora_alpha': 32, 'lora_dropout': 0.1, 'target_modules': ['q_proj', 'v_proj'], 'learning_rate': 0.0005, 'num_epochs': 1, 'max_steps': 20, 'save_frequency': 1, 'batch_size': 1, 'max_seq_length': 2048}, '_wandb': {}}
2025-09-01 13:31:03,445 INFO    MainThread:2472110 [wandb_init.py:init():854] starting backend
2025-09-01 13:31:03,658 INFO    MainThread:2472110 [wandb_init.py:init():857] sending inform_init request
2025-09-01 13:31:03,667 INFO    MainThread:2472110 [wandb_init.py:init():865] backend started and connected
2025-09-01 13:31:03,671 INFO    MainThread:2472110 [wandb_init.py:init():936] updated telemetry
2025-09-01 13:31:03,683 INFO    MainThread:2472110 [wandb_init.py:init():960] communicating run to backend with 90.0 second timeout
2025-09-01 13:31:04,284 INFO    MainThread:2472110 [wandb_init.py:init():1011] starting run threads in backend
2025-09-01 13:31:04,435 INFO    MainThread:2472110 [wandb_run.py:_console_start():2494] atexit reg
2025-09-01 13:31:04,435 INFO    MainThread:2472110 [wandb_run.py:_redirect():2342] redirect: wrap_raw
2025-09-01 13:31:04,436 INFO    MainThread:2472110 [wandb_run.py:_redirect():2411] Wrapping output streams.
2025-09-01 13:31:04,436 INFO    MainThread:2472110 [wandb_run.py:_redirect():2434] Redirects installed.
2025-09-01 13:31:04,438 INFO    MainThread:2472110 [wandb_init.py:init():1057] run started, returning control to user process
2025-09-01 13:31:05,095 INFO    wandb-AsyncioManager-main:2472110 [service_client.py:_forward_responses():84] Reached EOF.
2025-09-01 13:31:05,095 INFO    wandb-AsyncioManager-main:2472110 [mailbox.py:close():137] Closing mailbox, abandoning 1 handles.
2025-09-01 13:31:05,338 ERROR   wandb-AsyncioManager-main:2472110 [asyncio_manager.py:fn_wrap_exceptions():183] Uncaught exception in run_soon callback.
Traceback (most recent call last):
  File "/scratch/anaconda3/envs/myenv/lib/python3.11/site-packages/wandb/sdk/lib/asyncio_manager.py", line 181, in fn_wrap_exceptions
    await fn()
  File "/scratch/anaconda3/envs/myenv/lib/python3.11/site-packages/wandb/sdk/lib/service/service_client.py", line 65, in _send_server_request
    await self._writer.drain()
  File "/scratch/anaconda3/envs/myenv/lib/python3.11/asyncio/streams.py", line 392, in drain
    await self._protocol._drain_helper()
  File "/scratch/anaconda3/envs/myenv/lib/python3.11/asyncio/streams.py", line 166, in _drain_helper
    raise ConnectionResetError('Connection lost')
ConnectionResetError: Connection lost
2025-09-01 13:31:05,353 ERROR   wandb-AsyncioManager-main:2472110 [asyncio_manager.py:fn_wrap_exceptions():183] Uncaught exception in run_soon callback.
Traceback (most recent call last):
  File "/scratch/anaconda3/envs/myenv/lib/python3.11/site-packages/wandb/sdk/lib/asyncio_manager.py", line 181, in fn_wrap_exceptions
    await fn()
  File "/scratch/anaconda3/envs/myenv/lib/python3.11/site-packages/wandb/sdk/lib/service/service_client.py", line 65, in _send_server_request
    await self._writer.drain()
  File "/scratch/anaconda3/envs/myenv/lib/python3.11/asyncio/streams.py", line 392, in drain
    await self._protocol._drain_helper()
  File "/scratch/anaconda3/envs/myenv/lib/python3.11/asyncio/streams.py", line 166, in _drain_helper
    raise ConnectionResetError('Connection lost')
ConnectionResetError: Connection lost
2025-09-01 13:31:05,356 ERROR   wandb-AsyncioManager-main:2472110 [asyncio_manager.py:fn_wrap_exceptions():183] Uncaught exception in run_soon callback.
Traceback (most recent call last):
  File "/scratch/anaconda3/envs/myenv/lib/python3.11/site-packages/wandb/sdk/lib/asyncio_manager.py", line 181, in fn_wrap_exceptions
    await fn()
  File "/scratch/anaconda3/envs/myenv/lib/python3.11/site-packages/wandb/sdk/lib/service/service_client.py", line 65, in _send_server_request
    await self._writer.drain()
  File "/scratch/anaconda3/envs/myenv/lib/python3.11/asyncio/streams.py", line 392, in drain
    await self._protocol._drain_helper()
  File "/scratch/anaconda3/envs/myenv/lib/python3.11/asyncio/streams.py", line 166, in _drain_helper
    raise ConnectionResetError('Connection lost')
ConnectionResetError: Connection lost
